2025-07-19 13:55:14,665 -  nornir.core -     INFO -        run() - Running task 'netmiko_send_command' with args {'command_string': 'show version', 'read_timeout': 30} on 1 hosts
2025-07-19 13:55:17,745 - nornir.core.task -    ERROR -      start() - Host 'spine1': task 'netmiko_send_command' failed with traceback:
Traceback (most recent call last):
  File "/home/lab/net-chatbot/.venv/lib/python3.12/site-packages/netmiko/base_connection.py", line 1146, in establish_connection
    self.remote_conn_pre.connect(**ssh_connect_params)
  File "/home/lab/net-chatbot/.venv/lib/python3.12/site-packages/paramiko/client.py", line 409, in connect
    raise NoValidConnectionsError(errors)
paramiko.ssh_exception.NoValidConnectionsError: [Errno None] Unable to connect to port 22 on 172.20.20.100

During handling of the above exception, another exception occurred:

Traceback (most recent call last):
  File "/home/lab/net-chatbot/.venv/lib/python3.12/site-packages/nornir/core/task.py", line 98, in start
    r = self.task(self, **self.params)
        ^^^^^^^^^^^^^^^^^^^^^^^^^^^^^^
  File "/home/lab/net-chatbot/.venv/lib/python3.12/site-packages/nornir_netmiko/tasks/netmiko_send_command.py", line 26, in netmiko_send_command
    net_connect = task.host.get_connection(CONNECTION_NAME, task.nornir.config)
                  ^^^^^^^^^^^^^^^^^^^^^^^^^^^^^^^^^^^^^^^^^^^^^^^^^^^^^^^^^^^^^
  File "/home/lab/net-chatbot/.venv/lib/python3.12/site-packages/nornir/core/inventory.py", line 476, in get_connection
    self.open_connection(
  File "/home/lab/net-chatbot/.venv/lib/python3.12/site-packages/nornir/core/inventory.py", line 528, in open_connection
    conn_obj.open(
  File "/home/lab/net-chatbot/.venv/lib/python3.12/site-packages/nornir_netmiko/connections/netmiko.py", line 59, in open
    connection = ConnectHandler(**parameters)
                 ^^^^^^^^^^^^^^^^^^^^^^^^^^^^
  File "/home/lab/net-chatbot/.venv/lib/python3.12/site-packages/netmiko/ssh_dispatcher.py", line 460, in ConnectHandler
    return ConnectionClass(*args, **kwargs)
           ^^^^^^^^^^^^^^^^^^^^^^^^^^^^^^^^
  File "/home/lab/net-chatbot/.venv/lib/python3.12/site-packages/netmiko/base_connection.py", line 495, in __init__
    self._open()
  File "/home/lab/net-chatbot/.venv/lib/python3.12/site-packages/netmiko/base_connection.py", line 500, in _open
    self.establish_connection()
  File "/home/lab/net-chatbot/.venv/lib/python3.12/site-packages/netmiko/base_connection.py", line 1168, in establish_connection
    raise NetmikoTimeoutException(msg)
netmiko.exceptions.NetmikoTimeoutException: TCP connection to device failed.

Common causes of this problem are:
1. Incorrect hostname or IP address.
2. Wrong TCP port.
3. Intermediate firewall blocking access.

Device settings: arista_eos 172.20.20.100:22



2025-07-19 13:59:33,815 -  nornir.core -     INFO -        run() - Running task 'netmiko_send_command' with args {'command_string': 'show version', 'read_timeout': 30} on 1 hosts
